Failure # 1 (occurred at 2022-04-04_23-55-08)
Traceback (most recent call last):
  File "C:\Users\mandy\anaconda3\envs\gpu2\lib\site-packages\ray\tune\trial_runner.py", line 739, in _process_trial
    results = self.trial_executor.fetch_result(trial)
  File "C:\Users\mandy\anaconda3\envs\gpu2\lib\site-packages\ray\tune\ray_trial_executor.py", line 746, in fetch_result
    result = ray.get(trial_future[0], timeout=DEFAULT_GET_TIMEOUT)
  File "C:\Users\mandy\anaconda3\envs\gpu2\lib\site-packages\ray\_private\client_mode_hook.py", line 82, in wrapper
    return func(*args, **kwargs)
  File "C:\Users\mandy\anaconda3\envs\gpu2\lib\site-packages\ray\worker.py", line 1621, in get
    raise value.as_instanceof_cause()
ray.exceptions.RayTaskError(TuneError): [36mray::ImplicitFunc.train_buffered()[39m (pid=23188, ip=192.168.1.200, repr=<types.ImplicitFunc object at 0x000001EE6472E8B0>)
  File "python\ray\_raylet.pyx", line 536, in ray._raylet.execute_task
  File "python\ray\_raylet.pyx", line 486, in ray._raylet.execute_task.function_executor
  File "C:\Users\mandy\anaconda3\envs\gpu2\lib\site-packages\ray\_private\function_manager.py", line 563, in actor_method_executor
    return method(__ray_actor, *args, **kwargs)
  File "C:\Users\mandy\anaconda3\envs\gpu2\lib\site-packages\ray\tune\trainable.py", line 178, in train_buffered
    result = self.train()
  File "C:\Users\mandy\anaconda3\envs\gpu2\lib\site-packages\ray\tune\trainable.py", line 237, in train
    result = self.step()
  File "C:\Users\mandy\anaconda3\envs\gpu2\lib\site-packages\ray\tune\function_runner.py", line 379, in step
    self._report_thread_runner_error(block=True)
  File "C:\Users\mandy\anaconda3\envs\gpu2\lib\site-packages\ray\tune\function_runner.py", line 526, in _report_thread_runner_error
    raise TuneError(
ray.tune.error.TuneError: Trial raised an exception. Traceback:
[36mray::ImplicitFunc.train_buffered()[39m (pid=23188, ip=192.168.1.200, repr=<types.ImplicitFunc object at 0x000001EE6472E8B0>)
  File "C:\Users\mandy\anaconda3\envs\gpu2\lib\site-packages\ray\tune\function_runner.py", line 260, in run
    self._entrypoint()
  File "C:\Users\mandy\anaconda3\envs\gpu2\lib\site-packages\ray\tune\function_runner.py", line 328, in entrypoint
    return self._trainable_func(self.config, self._status_reporter,
  File "C:\Users\mandy\anaconda3\envs\gpu2\lib\site-packages\ray\tune\function_runner.py", line 594, in _trainable_func
    output = fn()
  File "C:\Users\mandy\anaconda3\envs\gpu2\lib\site-packages\transformers\integrations.py", line 282, in dynamic_modules_import_trainable
    return trainable(*args, **kwargs)
  File "C:\Users\mandy\anaconda3\envs\gpu2\lib\site-packages\ray\tune\utils\trainable.py", line 344, in inner
    trainable(config, **fn_kwargs)
  File "C:\Users\mandy\anaconda3\envs\gpu2\lib\site-packages\transformers\integrations.py", line 183, in _objective
    local_trainer.train(resume_from_checkpoint=checkpoint, trial=trial)
  File "C:\Users\mandy\anaconda3\envs\gpu2\lib\site-packages\transformers\trainer.py", line 1383, in train
    self._maybe_log_save_evaluate(tr_loss, model, trial, epoch, ignore_keys_for_eval)
  File "C:\Users\mandy\anaconda3\envs\gpu2\lib\site-packages\transformers\trainer.py", line 1491, in _maybe_log_save_evaluate
    metrics = self.evaluate(ignore_keys=ignore_keys_for_eval)
  File "C:\Users\mandy\anaconda3\envs\gpu2\lib\site-packages\transformers\trainer.py", line 2113, in evaluate
    output = eval_loop(
  File "C:\Users\mandy\anaconda3\envs\gpu2\lib\site-packages\transformers\trainer.py", line 2354, in evaluation_loop
    metrics = self.compute_metrics(EvalPrediction(predictions=all_preds, label_ids=all_labels))
  File "C:\Users\mandy\Documents\transformer-project\ccai-bert-train\utils\scorer.py", line 123, in compute_metrics_transformers_lcpn
    labels = [self.transformer_decoder([label])[0] for label in raw_labels]
  File "C:\Users\mandy\Documents\transformer-project\ccai-bert-train\utils\scorer.py", line 123, in <listcomp>
    labels = [self.transformer_decoder([label])[0] for label in raw_labels]
TypeError: 'dict' object is not callable

